ERROR 2018-08-22 21:37:14,455 exception 2624 123145564368896 Internal Server Error: /showtasks/
Traceback (most recent call last):
  File "/usr/local/lib/python3.6/site-packages/django/template/base.py", line 475, in parse
    compile_func = self.tags[command]
KeyError: 'static'

During handling of the above exception, another exception occurred:

Traceback (most recent call last):
  File "/usr/local/lib/python3.6/site-packages/django/core/handlers/exception.py", line 35, in inner
    response = get_response(request)
  File "/usr/local/lib/python3.6/site-packages/django/core/handlers/base.py", line 128, in _get_response
    response = self.process_exception_by_middleware(e, request)
  File "/usr/local/lib/python3.6/site-packages/django/core/handlers/base.py", line 126, in _get_response
    response = wrapped_callback(request, *callback_args, **callback_kwargs)
  File "/Users/bcj/Documents/科技部/EItools/EItools/view.py", line 25, in showTask
    return render(request,"tasks.html",{'task_list': tasks})
  File "/usr/local/lib/python3.6/site-packages/django/shortcuts.py", line 36, in render
    content = loader.render_to_string(template_name, context, request, using=using)
  File "/usr/local/lib/python3.6/site-packages/django/template/loader.py", line 61, in render_to_string
    template = get_template(template_name, using=using)
  File "/usr/local/lib/python3.6/site-packages/django/template/loader.py", line 15, in get_template
    return engine.get_template(template_name)
  File "/usr/local/lib/python3.6/site-packages/django/template/backends/django.py", line 34, in get_template
    return Template(self.engine.get_template(template_name), self)
  File "/usr/local/lib/python3.6/site-packages/django/template/engine.py", line 144, in get_template
    template, origin = self.find_template(template_name)
  File "/usr/local/lib/python3.6/site-packages/django/template/engine.py", line 126, in find_template
    template = loader.get_template(name, skip=skip)
  File "/usr/local/lib/python3.6/site-packages/django/template/loaders/base.py", line 30, in get_template
    contents, origin, origin.template_name, self.engine,
  File "/usr/local/lib/python3.6/site-packages/django/template/base.py", line 160, in __init__
    self.nodelist = self.compile_nodelist()
  File "/usr/local/lib/python3.6/site-packages/django/template/base.py", line 198, in compile_nodelist
    return parser.parse()
  File "/usr/local/lib/python3.6/site-packages/django/template/base.py", line 477, in parse
    self.invalid_block_tag(token, command, parse_until)
  File "/usr/local/lib/python3.6/site-packages/django/template/base.py", line 539, in invalid_block_tag
    "or load this tag?" % (token.lineno, command)
django.template.exceptions.TemplateSyntaxError: Invalid block tag on line 488: 'static'. Did you forget to register or load this tag?
ERROR 2018-08-22 21:37:14,551 basehttp 2624 123145564368896 "GET /showtasks/ HTTP/1.1" 500 130753
WARNING 2018-08-22 21:37:14,928 base 2624 123145569624064 Not Found: /favicon.ico
WARNING 2018-08-22 21:37:14,929 basehttp 2624 123145569624064 "GET /favicon.ico HTTP/1.1" 404 2806
INFO 2018-08-22 21:39:20,890 task 2732 123145423642624 get all task
INFO 2018-08-22 21:39:20,909 basehttp 2732 123145423642624 "GET /gettasks/ HTTP/1.1" 200 455
WARNING 2018-08-22 21:49:09,220 base 2933 123145503989760 Not Found: /gettasks/0/4
WARNING 2018-08-22 21:49:09,221 basehttp 2933 123145503989760 "GET /gettasks/0/4 HTTP/1.1" 404 2825
WARNING 2018-08-22 21:49:18,210 base 2933 123145509244928 Not Found: /showtasks/0/4
WARNING 2018-08-22 21:49:18,210 basehttp 2933 123145509244928 "GET /showtasks/0/4 HTTP/1.1" 404 2828
WARNING 2018-08-22 21:49:25,371 base 2933 123145503989760 Not Found: /showtasks/0/4/
WARNING 2018-08-22 21:49:25,372 basehttp 2933 123145503989760 "GET /showtasks/0/4/ HTTP/1.1" 404 2831
WARNING 2018-08-22 21:51:52,056 base 3006 123145483943936 Not Found: /showtasks/0/4/
WARNING 2018-08-22 21:51:52,057 basehttp 3006 123145483943936 "GET /showtasks/0/4/ HTTP/1.1" 404 2831
INFO 2018-08-22 21:53:42,081 task 3062 123145589940224 get all task
INFO 2018-08-22 21:53:42,096 basehttp 3062 123145589940224 "GET /showtasks/0/4/ HTTP/1.1" 200 455
WARNING 2018-08-22 21:54:00,713 base 3062 123145600450560 Not Found: /struts2-rest-showcase/orders.xhtml
WARNING 2018-08-22 21:54:00,714 basehttp 3062 123145600450560 "GET /struts2-rest-showcase/orders.xhtml HTTP/1.1" 404 2893
WARNING 2018-08-22 21:54:00,861 base 3062 123145600450560 Not Found: /index.action
WARNING 2018-08-22 21:54:00,861 basehttp 3062 123145600450560 "GET /index.action HTTP/1.1" 404 2827
WARNING 2018-08-22 21:54:00,996 base 3062 123145600450560 Not Found: /index.do
WARNING 2018-08-22 21:54:00,997 basehttp 3062 123145600450560 "GET /index.do HTTP/1.1" 404 2815
INFO 2018-08-22 22:05:36,753 task 3685 123145436405760 get all task
ERROR 2018-08-22 22:05:36,754 exception 3685 123145436405760 Internal Server Error: /showtasks/0/4/
Traceback (most recent call last):
  File "/usr/local/lib/python3.6/site-packages/django/core/handlers/exception.py", line 35, in inner
    response = get_response(request)
  File "/usr/local/lib/python3.6/site-packages/django/core/handlers/base.py", line 128, in _get_response
    response = self.process_exception_by_middleware(e, request)
  File "/usr/local/lib/python3.6/site-packages/django/core/handlers/base.py", line 126, in _get_response
    response = wrapped_callback(request, *callback_args, **callback_kwargs)
  File "/Users/bcj/Documents/科技部/EItools/EItools/crawler/task.py", line 20, in get_all_tasks
    tasks=mongo_client.get_all_task(offset,size)
  File "/Users/bcj/Documents/科技部/EItools/EItools/client/mongo_client.py", line 25, in get_all_task
    if size > 0 and offset >= 0:
TypeError: '>' not supported between instances of 'str' and 'int'
ERROR 2018-08-22 22:05:36,830 basehttp 3685 123145436405760 "GET /showtasks/0/4/ HTTP/1.1" 500 66427
INFO 2018-08-22 22:06:56,793 task 3735 123145493590016 get all task
INFO 2018-08-22 22:06:56,826 basehttp 3735 123145493590016 "GET /showtasks/0/4/ HTTP/1.1" 200 20
INFO 2018-08-22 22:07:37,483 task 3777 123145393905664 get all task
INFO 2018-08-22 22:07:37,541 basehttp 3777 123145393905664 "GET /showtasks/0/4/ HTTP/1.1" 200 562
INFO 2018-08-22 22:08:21,934 task 3816 123145402736640 get all task
INFO 2018-08-22 22:08:22,034 basehttp 3816 123145402736640 "GET /showtasks/0/4/ HTTP/1.1" 200 506
ERROR 2018-08-22 22:33:30,836 exception 4508 123145497059328 Internal Server Error: /save/task/
Traceback (most recent call last):
  File "/usr/local/lib/python3.6/site-packages/django/utils/datastructures.py", line 77, in __getitem__
    list_ = super().__getitem__(key)
KeyError: 'file_name'

During handling of the above exception, another exception occurred:

Traceback (most recent call last):
  File "/usr/local/lib/python3.6/site-packages/django/core/handlers/exception.py", line 35, in inner
    response = get_response(request)
  File "/usr/local/lib/python3.6/site-packages/django/core/handlers/base.py", line 128, in _get_response
    response = self.process_exception_by_middleware(e, request)
  File "/usr/local/lib/python3.6/site-packages/django/core/handlers/base.py", line 126, in _get_response
    response = wrapped_callback(request, *callback_args, **callback_kwargs)
  File "/Users/bcj/Documents/科技部/EItools/EItools/crawler/task.py", line 34, in upload_task
    file_name=request.POST['file_name']
  File "/usr/local/lib/python3.6/site-packages/django/utils/datastructures.py", line 79, in __getitem__
    raise MultiValueDictKeyError(key)
django.utils.datastructures.MultiValueDictKeyError: 'file_name'
ERROR 2018-08-22 22:33:30,930 basehttp 4508 123145497059328 "GET /save/task/ HTTP/1.1" 500 68371
ERROR 2018-08-22 22:33:39,715 exception 4508 123145497059328 Internal Server Error: /save/task/
Traceback (most recent call last):
  File "/usr/local/lib/python3.6/site-packages/django/utils/datastructures.py", line 77, in __getitem__
    list_ = super().__getitem__(key)
KeyError: 'file_name'

During handling of the above exception, another exception occurred:

Traceback (most recent call last):
  File "/usr/local/lib/python3.6/site-packages/django/core/handlers/exception.py", line 35, in inner
    response = get_response(request)
  File "/usr/local/lib/python3.6/site-packages/django/core/handlers/base.py", line 128, in _get_response
    response = self.process_exception_by_middleware(e, request)
  File "/usr/local/lib/python3.6/site-packages/django/core/handlers/base.py", line 126, in _get_response
    response = wrapped_callback(request, *callback_args, **callback_kwargs)
  File "/Users/bcj/Documents/科技部/EItools/EItools/crawler/task.py", line 34, in upload_task
    file_name=request.POST['file_name']
  File "/usr/local/lib/python3.6/site-packages/django/utils/datastructures.py", line 79, in __getitem__
    raise MultiValueDictKeyError(key)
django.utils.datastructures.MultiValueDictKeyError: 'file_name'
ERROR 2018-08-22 22:33:39,764 basehttp 4508 123145497059328 "POST /save/task/ HTTP/1.1" 500 68379
INFO 2018-08-22 22:37:31,804 basehttp 4749 123145400528896 "POST /save/task/ HTTP/1.1" 200 29
INFO 2018-08-22 22:37:50,313 basehttp 4749 123145400528896 "GET /save/task/ HTTP/1.1" 200 29
INFO 2018-08-22 22:38:34,476 basehttp 4793 123145553813504 "POST /save/task/ HTTP/1.1" 200 29
INFO 2018-08-22 22:40:09,460 basehttp 4793 123145553813504 "POST /save/task/ HTTP/1.1" 200 29
INFO 2018-08-22 22:40:20,234 basehttp 4793 123145553813504 "POST /save/task/ HTTP/1.1" 200 29
INFO 2018-08-22 22:41:44,002 basehttp 4793 123145553813504 "POST /save/task/ HTTP/1.1" 200 26
INFO 2018-08-22 22:43:13,804 basehttp 4793 123145553813504 "POST /save/task/ HTTP/1.1" 200 26
INFO 2018-08-22 22:44:58,501 task 4911 123145529245696 get all task
INFO 2018-08-22 22:44:58,570 basehttp 4911 123145529245696 "GET /showtasks/0/4/ HTTP/1.1" 200 506
INFO 2018-08-22 22:45:04,110 basehttp 4911 123145529245696 "POST /save/task/ HTTP/1.1" 200 26
INFO 2018-08-22 22:45:04,242 crawl_information 4983 140736233636800 [Errno 2] No such file or directory: '/Users/bcj/Documents/科技部/EItools/media/file/张三'
INFO 2018-08-22 22:47:42,123 crawl_information 4911 123145529245696 crawl file info start
INFO 2018-08-22 22:47:42,187 crawl_information 4911 123145529245696 crawl file info end
INFO 2018-08-22 22:47:42,189 basehttp 4911 123145529245696 "POST /upload/crawlfile/ HTTP/1.1" 200 70
INFO 2018-08-22 22:48:33,944 crawl_information 5059 123145557540864 crawl file info start
INFO 2018-08-22 22:48:33,950 crawl_information 5059 123145557540864 crawl file info end
INFO 2018-08-22 22:48:33,951 basehttp 5059 123145557540864 "POST /upload/crawlfile/ HTTP/1.1" 200 57
INFO 2018-08-22 22:51:23,593 basehttp 5104 123145416237056 "GET /downloadfile/fjsfdsffds HTTP/1.1" 301 0
INFO 2018-08-22 22:53:39,630 basehttp 5169 123145494212608 "GET /downloadfile/fjsfdsffds HTTP/1.1" 301 0
INFO 2018-08-22 22:54:20,271 basehttp 5215 123145480937472 "GET /downloadfile/fjsfdsffds HTTP/1.1" 301 0
INFO 2018-08-22 22:54:35,225 basehttp 5215 123145480937472 "GET /downloadfile/fjsfdsffds HTTP/1.1" 301 0
ERROR 2018-08-22 22:54:53,883 exception 5215 123145480937472 Internal Server Error: /downloadfile/fjsfdsffds/
Traceback (most recent call last):
  File "/usr/local/lib/python3.6/site-packages/django/core/handlers/exception.py", line 35, in inner
    response = get_response(request)
  File "/usr/local/lib/python3.6/site-packages/django/core/handlers/base.py", line 128, in _get_response
    response = self.process_exception_by_middleware(e, request)
  File "/usr/local/lib/python3.6/site-packages/django/core/handlers/base.py", line 126, in _get_response
    response = wrapped_callback(request, *callback_args, **callback_kwargs)
  File "/Users/bcj/Documents/科技部/EItools/EItools/crawler/task.py", line 51, in export_data
    task=mongo_client.get_task_by_Id(taskid)
  File "/Users/bcj/Documents/科技部/EItools/EItools/client/mongo_client.py", line 61, in get_task_by_Id
    return self.task_col.find_one({"_id": ObjectId(id)})
  File "/usr/local/lib/python3.6/site-packages/bson/objectid.py", line 110, in __init__
    self.__validate(oid)
  File "/usr/local/lib/python3.6/site-packages/bson/objectid.py", line 206, in __validate
    _raise_invalid_id(oid)
  File "/usr/local/lib/python3.6/site-packages/bson/objectid.py", line 52, in _raise_invalid_id
    " or a 24-character hex string" % oid)
bson.errors.InvalidId: 'fjsfdsffds' is not a valid ObjectId, it must be a 12-byte input or a 24-character hex string
ERROR 2018-08-22 22:54:53,950 basehttp 5215 123145480937472 "GET /downloadfile/fjsfdsffds/ HTTP/1.1" 500 75403
INFO 2018-08-22 22:56:58,074 basehttp 5271 123145558917120 "GET /downloadfile/fjsfdsffds/ HTTP/1.1" 200 25
